Workbook

Sheet Raw_Sales_Data
A1: Order_ID | B1: Order_Date | C1: Customer_ID | D1: Product | E1: Category | F1: Region | G1: Salesperson | H1: Quantity | I1: Unit_Price | J1: Discount | K1: Revenue | L1: Cost | M1: Profit | N1: Profit_Margin
A2: ORD-00101 | B2: 45658 | C2: CUST-1221 | D2: Printer | E2: Office Equipment | F2: East | G2: Daniel | H2: 3 | I2: 210 | J2: 0 | K2: 630 | L2: 375 | M2: 255 | N2: 0.4048
A3: ORD-00303 | B3: 45658 | C3: CUST-1050 | D3: Keyboard | E3: Accessories | F3: South | G3: Grace | H3: 6 | I3: 65 | J3: 0 | K3: 390 | L3: 210 | M3: 180 | N3: 0.4615
A4: ORD-00332 | B4: 45658 | C4: CUST-1174 | D4: Laptop | E4: Electronics | F4: North | G4: Grace | H4: 8 | I4: 850 | J4: 0.05 | K4: 6460 | L4: 4160 | M4: 2300 | N4: 0.356
A5: ORD-00410 | B5: 45658 | C5: CUST-1097 | D5: Desk | E5: Furniture | F5: South | G5: Chinedu | H5: 4 | I5: 320 | J5: 0 | K5: 1280 | L5: 780 | M5: 500 | N5: 0.3906
A6: ORD-00151 | B6: 45661 | C6: CUST-1139 | D6: Keyboard | E6: Accessories | F6: West | G6: Chinedu | H6: 6 | I6: 65 | J6: 0.02 | K6: 382.2 | L6: 210 | M6: 172.2 | N6: 0.4505
A7: ORD-00070 | B7: 45662 | C7: CUST-1063 | D7: Desk | E7: Furniture | F7: East | G7: Chinedu | H7: 8 | I7: 320 | J7: 0.05 | K7: 2432 | L7: 1560 | M7: 872 | N7: 0.3586
A8: ORD-00268 | B8: 45662 | C8: CUST-1052 | D8: Headset | E8: Accessories | F8: North | G8: Daniel | H8: 1 | I8: 75 | J8: 0.05 | K8: 71.25 | L8: 40 | M8: 31.25 | N8: 0.4386
A9: ORD-00375 | B9: 45662 | C9: CUST-1145 | D9: Laptop | E9: Electronics | F9: East | G9: Ibrahim | H9: 9 | I9: 850 | J9: 0.15 | K9: 6502.5 | L9: 4680 | M9: 1822.5 | N9: 0.2803
A10: ORD-00497 | B10: 45662 | C10: CUST-1122 | D10: Keyboard | E10: Accessories | F10: South | G10: Fatima | H10: 7 | I10: 65 | J10: 0.02 | K10: 445.9 | L10: 245 | M10: 200.9 | N10: 0.4505
A11: ORD-00396 | B11: 45663 | C11: CUST-1084 | D11: Mouse | E11: Accessories | F11: West | G11: Amina | H11: 5 | I11: 35 | J11: 0.1 | K11: 157.5 | L11: 90 | M11: 67.5 | N11: 0.4286
A12: ORD-00260 | B12: 45664 | C12: CUST-1164 | D12: Keyboard | E12: Accessories | F12: East | G12: Ibrahim | H12: 1 | I12: 65 | J12: 0.05 | K12: 61.75 | L12: 35 | M12: 26.75 | N12: 0.4332
A13: ORD-00342 | B13: 45665 | C13: CUST-1021 | D13: Mouse | E13: Accessories | F13: West | G13: Grace | H13: 2 | I13: 35 | J13: 0.05 | K13: 66.5 | L13: 36 | M13: 30.5 | N13: 0.4586
... A501: ORD-00374 | B501: 46022 | C501: CUST-1210 | D501: Headset | E501: Accessories | F501: South | G501: Grace | H501: 3 | I501: 75 | J501: 0.05 | K501: 213.75 | L501: 120 | M501: 93.75 | N501: 0.4386

Sheet Sales Analysis
A1: Metric | B1: Value
A2: Total Revenue | B2: =SUM(Raw_Sales_Data!K2:K501) -> 680363.2
A3: Total Cost | B3: =SUM(Raw_Sales_Data!L2:L501) -> 429297
A4: Total Profit | B4: =SUM(Raw_Sales_Data!M2:M501) -> 251066.2
A5: Total Units Sold | B5: =SUM(Raw_Sales_Data!H2:H501) -> 2710
A6: Number of Orders | B6: =COUNTA(Raw_Sales_Data!A2:A501) -> 500
A7: Average Order Value | B7: =B2/B6 -> 1360.7264
A8: Overall Profit Margin | B8: =B4/B2 -> 0.3690179
A10: 1. The Dataset contains 500 orders
A11: 2. Those orders generated 680,363.20 in revenue.
A12: 3. Total cost was 429,297.00.
A13: 4. The resulting profit was 251,066.20.
A14: 5. Customers purchased 2,710 units
A15: 6. Average revenue per order was 1,360.73
A16: 7. Overall profit margin was 36.90%

Sheet Product Analysis
B1: Product Performance | H1: Product Analysis Table
A3: Product | B3: Revenue | C3: Profit | D3: Profit Margin | G3: Product | H3: Sum of Revenue | I3: Sum of Profit | J3: Profit Margin
A4: Desk | B4: 105024 | C4: 38334 | D4: 0.365 | G4: Desk | H4: 105024 | I4: 38334 | J4: =I4/H4 -> 0.36500229
A5: Headset | B5: 29112 | C5: 12832 | D5: 0.4408 | G5: Headset | H5: 29112 | I5: 12832 | J5: =I5/H5 -> 0.44078043
A6: Keyboard | B6: 22100 | C6: 9745 | D6: 0.441 | G6: Keyboard | H6: 22100 | I6: 9745 | J6: =I6/H6 -> 0.44095023
A7: Laptop | B7: 323756.5 | C7: 114716.5 | D7: 0.3543 | G7: Laptop | H7: 323756.5 | I7: 114716.5 | J7: =I7/H7 -> 0.35432957
A8: Monitor | B8: 68012 | C8: 24662 | D8: 0.3626 | G8: Monitor | H8: 68012 | I8: 24662 | J8: =I8/H8 -> 0.36261248
A9: Mouse | B9: 13370 | C9: 6188 | D9: 0.4628 | G9: Mouse | H9: 13370 | I9: 6188 | J9: =I9/H9 -> 0.46282723
A10: Office Chair | B10: 62299.2 | C10: 23149.2 | D10: 0.3716 | G10: Office Chair | H10: 62299.2 | I10: 23149.2 | J10: =I10/H10 -> 0.37158102
A11: Printer | B11: 56689.5 | C11: 21439.5 | D11: 0.3782 | G11: Printer | H11: 56689.5 | I11: 21439.5 | J11: =I11/H11 -> 0.37819173
A12: Overall | B12: 680363.2 | C12: 251066.2 | D12: 0.369 | G12: Total Result | H12: 680363.2 | I12: 251066.2 | J12: =I12/H12 -> 0.3690179
A16: Category Performance | H16: Category Analysis Table
A18: Category | B18: Revenue | C18: Profit | D18: Quantity | E18: Profit Margin | G18: Category | H18: Sum of Revenue | I18: Sum of Profit | J18: Sum of Quantity | K18: Profit Margin
A19: Accessories | B19: 64582 | C19: 28765 | D19: 1159 | E19: 0.4454 | G19: Accessories | H19: 64582 | I19: 28765 | J19: 1159 | K19: =I19/H19 -> 0.44540274
A20: Electronics | B20: 391768.5 | C20: 139378.5 | D20: 657 | E20: 0.3558 | G20: Electronics | H20: 391768.5 | I20: 139378.5 | J20: 657 | K20: =I20/H20 -> 0.3557675
A21: Furniture | B21: 167323.2 | C21: 61483.2 | D21: 612 | E21: 0.3675 | G21: Furniture | H21: 167323.2 | I21: 61483.2 | J21: 612 | K21: =I21/H21 -> 0.36745173
A22: Office Equipment | B22: 56689.5 | C22: 21439.5 | D22: 282 | E22: 0.3782 | G22: Office Equipment | H22: 56689.5 | I22: 21439.5 | J22: 282 | K22: =I22/H22 -> 0.37819173
A23: Grand Total | B23: 680363.2 | C23: 251066.2 | D23: 2710 | E23: 0.369 | G23: Total Result | H23: 680363.2 | I23: 251066.2 | J23: 2710 | K23: =I23/H23 -> 0.3690179
H25: Regional Analysis Table
A26: Regional Performance
G27: Region | H27: Sum of Revenue | I27: Sum of Profit | J27: Sum of Quantity | K27: Profit Margin
A28: Region | B28: Revenue | C28: Profit | D28: Quantity | E28: Profit Margin | G28: East | H28: 202585.5 | I28: 73182.5 | J28: 717 | K28: =I28/H28 -> 0.36124254
A29: East | B29: 202585.5 | C29: 73182.5 | D29: 717 | E29: 0.3612 | G29: North | H29: 146616.35 | I29: 54639.35 | J29: 652 | K29: =I29/H29 -> 0.37266887
A30: North | B30: 146616.35 | C30: 54639.35 | D30: 652 | E30: 0.3727 | G30: South | H30: 180766.1 | I30: 67928.1 | J30: 733 | K30: =I30/H30 -> 0.37577898
A31: South | B31: 180766.1 | C31: 67928.1 | D31: 733 | E31: 0.3758 | G31: West | H31: 150395.25 | I31: 55316.25 | J31: 608 | K31: =I31/H31 -> 0.36780583
A32: West | B32: 150395.25 | C32: 55316.25 | D32: 608 | E32: 0.3678 | G32: Total Result | H32: 680363.2 | I32: 251066.2 | J32: 2710 | K32: =I32/H32 -> 0.3690179
A33: Grand Total | B33: 680363.2 | C33: 251066.2 | D33: 2710 | E33: 0.369
H34: Sales Person Analysis Table
A36: Salesperson Performance | G36: Row Labels | H36: Sum of Revenue | I36: Sum of Profit | J36: Sum of Quantity | K36: Profit Margin
G37: Amina | H37: 110903.1 | I37: 41409.1 | J37: 464 | K37: =I37/H37 -> 0.37338091
A38: Salesperson | B38: Revenue | C38: Profit | D38: Quantity | E38: Profit Margin | G38: Chinedu | H38: 118511.85 | I38: 43530.85 | J38: 486 | K38: =I38/H38 -> 0.36731221
A39: Amina | B39: 110903.1 | C39: 41409.1 | D39: 464 | E39: 0.3734 | G39: Daniel | H39: 122137.15 | I39: 45274.15 | J39: 460 | K39: =I39/H39 -> 0.37068288
A40: Chinedu | B40: 118511.85 | C40: 43530.85 | D40: 486 | E40: 0.3673 | G40: Fatima | H40: 100996.6 | I40: 36718.6 | J40: 350 | K40: =I40/H40 -> 0.36356273
A41: Daniel | B41: 122137.15 | C41: 45274.15 | D41: 460 | E41: 0.3707 | G41: Grace | H41: 134616.45 | I41: 49688.45 | J41: 524 | K41: =I41/H41 -> 0.36911128
A42: Fatima | B42: 100996.6 | C42: 36718.6 | D42: 350 | E42: 0.3636 | G42: Ibrahim | H42: 93198.05 | I42: 34445.05 | J42: 426 | K42: =I42/H42 -> 0.36958981
A43: Grace | B43: 134616.45 | C43: 49688.45 | D43: 524 | E43: 0.3691 | G43: Grand Total | H43: 680363.2 | I43: 251066.2 | J43: 2710 | K43: =I43/H43 -> 0.3690179
A44: Ibrahim | B44: 93198.05 | C44: 34445.05 | D44: 426 | E44: 0.3696
A45: Grand Total | B45: 680363.2 | C45: 251066.2 | D45: 2710 | E45: 0.369 | H45: Monthly Sale Trend
G47: Row Labels | H47: Sum of Revenue | I47: Sum of Profit | J47: Sum of Quantity | K47: Profit Margin
A48: Monthly Sales Trend | G48: 2025 | H48: 680363.2 | I48: 251066.2 | J48: 2710
...

Sheet Data Inspection
A1: Check | B1: Expected Result | C1: Actual Result | D1: Status | E1: Notes
A2: Record Count | B2: 500 | C2: 500 | D2: PASS | E2: 500 sales records identified
A3: Column Count | B3: 14 | C3: 14 | D3: PASS | E3: All expected fields are present
A4: Date Range | B4: Jan 1- Dec 31-2025 | C4: Jan 1–Dec 31, 2025 | D4: PASS | E4: Dates cover the expected 2025 period
A5: Quantity | B5: Positive | C5: Min = 1, Max = 10, Zero/negative = 0 | D5: PASS | E5: All quantities are within the expected range
A6: Unit Price | B6: Positive | C6: Min = 35, Max = 850, Zero/negative = 0 | D6: PASS | E6: All unit prices are positive
A7: Discount | B7: 0–15% | C7: Min = 0%, Max = 15%, Zero count = 154, Out-of-range = 0 | D7: PASS | E7: All discount values are within the expected 0–15% range.
A8: Revenue | B8: Non-negative | C8: Min = 29.75; Negative values = 0 | D8: PASS | E8: All revenue values are non-negative
A9: Cost | B9: Non-negative | C9: Min = 18; Negative values = 0 | D9: PASS | E9: All cost values are non-negative
A10: Profit | B10: Revenue − Cost | C10: 0 mismatches | D10: PASS | E10: Profit reconciles with Revenue minus Cost for all 500 records
A11: Profit Margin | B11: Profit ÷ Revenue | C11: 0 mismatches | D11: PASS | E11: Profit Margin reconciles for all 500 records

Sheet Revenue by Category
B19: Category Performance
C21: Category | D21: Revenue | E21: Profit | F21: Quantity | G21: Profit Margin
C22: Accessories | D22: 64582 | E22: 28765 | F22: 1159 | G22: 0.4454
C23: Electronics | D23: 391768.5 | E23: 139378.5 | F23: 657 | G23: 0.3558
C24: Furniture | D24: 167323.2 | E24: 61483.2 | F24: 612 | G24: 0.3675
C25: Office Equipment | D25: 56689.5 | E25: 21439.5 | F25: 282 | G25: 0.3782
C26: Grand Total | D26: 680363.2 | E26: 251066.2 | F26: 2710 | G26: 0.369

Sheet Dashboard
A1: SALES PERFORMANCE DASHBOARD
A2: 2025 Sales Analysis
A4: TOTAL REVENUE | C4: TOTAL PROFIT | E4: UNITS SOLD | G4: PROFIT MARGIN
A5: ='Sales Analysis'!B2 -> 680363.2 | C5: ='Sales Analysis'!B4 -> 251066.2 | E5: ='Sales Analysis'!B5 -> 2710 | G5: ='Sales Analysis'!B8 -> 0.3690179

Sheet Regional Revenue
B18: Regional Performance
B20: Region | C20: Revenue | D20: Profit | E20: Quantity | F20: Profit Margin
B21: East | C21: 202585.5 | D21: 73182.5 | E21: 717 | F21: 0.3612
B22: North | C22: 146616.35 | D22: 54639.35 | E22: 652 | F22: 0.3727
B23: South | C23: 180766.1 | D23: 67928.1 | E23: 733 | F23: 0.3758
B24: West | C24: 150395.25 | D24: 55316.25 | E24: 608 | F24: 0.3678
B25: Grand Total | C25: 680363.2 | D25: 251066.2 | E25: 2710 | F25: 0.369

Sheet Monthly Revenue
B20: Monthly Sales Trend
B22: Month | C22: Revenue | D22: Profit | E22: Quantity | F22: Profit Margin
B23: Jan | C23: 37598.45 | D23: 13649.45 | E23: 157 | F23: 0.363
B24: Feb | C24: 57939.1 | D24: 21803.1 | E24: 270 | F24: 0.3763
B25: Mar | C25: 52832.35 | D25: 19522.35 | E25: 178 | F25: 0.3695
B26: Apr | C26: 51742.25 | D26: 18384.25 | E26: 222 | F26: 0.3553
B27: May | C27: 48148 | D27: 17946 | E27: 241 | F27: 0.3727
B28: Jun | C28: 69846.1 | D28: 26201.1 | E28: 264 | F28: 0.3751
B29: Jul | C29: 40244.35 | D29: 15074.35 | E29: 180 | F29: 0.3746
B30: Aug | C30: 68994.75 | D30: 25363.75 | E30: 266 | F30: 0.3676
B31: Sep | C31: 82880.95 | D31: 30936.95 | E31: 278 | F31: 0.3733
B32: Oct | C32: 44639.1 | D32: 16444.1 | E32: 191 | F32: 0.3684
B33: Nov | C33: 62686.15 | D33: 23158.15 | E33: 199 | F33: 0.3694
B34: Dec | C34: 62811.65 | D34: 22582.65 | E34: 264 | F34: 0.3595
B35: Grand Total | C35: 680363.2 | D35: 251066.2 | E35: 2710 | F35: 0.369
